Great question! Error handling in JavaScript, especially with `try...catch` blocks and nested functions, can be tricky at first. Let me break it down for you.

### How Error Handling Works in JavaScript
1. When an error occurs (via `throw`), JavaScript stops executing the current block and looks for the nearest `try...catch` to handle it.
2. If the error occurs inside a nested function, the JavaScript runtime bubbles the error up to the nearest enclosing `try...catch` block. 
3. If there is no `try...catch` in the call stack, the error becomes **uncaught** and propagates up to the global error handler.

### Example Scenario
Let’s take a look at a simple example:

```javascript
function nestedFunction() {
  throw new Error("An error occurred in nestedFunction");
}

function outerFunction() {
  try {
    console.log("In the try block before calling nestedFunction");
    nestedFunction();
    console.log("This line will never run because an error was thrown");
  } catch (error) {
    console.log("Caught an error:", error.message);
  }
}

outerFunction();
```

### What Happens Here:
1. **Execution flow**:
   - The `try` block starts executing in `outerFunction`.
   - `nestedFunction` is called.
   - Inside `nestedFunction`, an error is thrown.

2. **Bubbling up**:
   - Since there’s no `try...catch` inside `nestedFunction`, the error is propagated up to `outerFunction`.

3. **Catching the error**:
   - The `try...catch` in `outerFunction` catches the error, and the `catch` block executes.

4. **Skipping code**:
   - Any code in the `try` block after the point where the error is thrown is skipped.

### A Visual Stack Trace:
1. Call `outerFunction` → Enter `try` block.
2. Call `nestedFunction` → Throw error.
3. Exit `nestedFunction` (error bubbles up).
4. Catch block in `outerFunction` handles the error.

---

### Errors in Deeply Nested Functions
If you have multiple levels of function calls:

```javascript
function level3() {
  throw new Error("Error in level3");
}

function level2() {
  level3();
}

function level1() {
  try {
    level2();
  } catch (error) {
    console.log("Caught an error:", error.message);
  }
}

level1();
```

Here’s what happens:
1. `level3` throws an error.
2. The error bubbles up through `level2` (no `try...catch` there).
3. It is finally caught in `level1`.

---

### Key Points:
1. **Error bubbling**:
   Errors propagate up the call stack until a `try...catch` block handles them.

2. **Error context**:
   When an error is thrown, it carries information about where it occurred (like the stack trace). You can access this in the `catch` block via `error.message` and `error.stack`.

3. **Uncaught errors**:
   If no `try...catch` handles the error, it propagates to the global context (Node.js or browser). In browsers, it triggers the `window.onerror` handler.

4. **Asynchronous functions**:
   If the error occurs inside an asynchronous function or `Promise`, it won’t be caught by a `try...catch` unless you use `async/await` or `.catch()`.

---

### For Promises and Async Functions:
Errors in promises require `.catch()` or `try...catch` with `async/await`:

```javascript
async function fetchData() {
  throw new Error("Network error");
}

async function main() {
  try {
    await fetchData();
  } catch (error) {
    console.log("Caught async error:", error.message);
  }
}

main();
```

Let me know if you’d like more examples or deeper insights!